Workbook

Sheet Inputs
A1: UK Property Flip Deal Calculator
A2: Inputs are blue (editable). Results are calculated. Tax rates are based on official guidance—always verify for your transaction.
A4: DEAL BASICS
A5: Purchase price | B5: 250000
A6: Expected sale price | B6: 320000
A7: Location (tax system) | B7: England & N. Ireland
A8: Buyer type | B8: Additional / Investor
A9: Non‑UK resident surcharge (Eng/N.I. only) | B9: No
A10: Project duration (months) | B10: 6
A12: ACQUISITION COSTS
A13: Transaction tax (auto) → | B13: =IF($D$13<>"",$D$13,IF($B$7="England & N. Ireland",(IF($B$8="First-time buyer",(IF($B$5<=500000,MAX(0,$B$5-300000)*0.05,(MAX(0,MIN($B$5,250000)-125000)*0.02+MAX(0,MIN($B$5,925000)-250000)*0.05+MAX(0,MIN($B$5,1500000)-925000)*0.1+MAX(0,$B$5-1500000)*0.12))),(MAX(0,MIN($B$5,250000)-125000)*0.02+MAX(0,MIN($B$5,925000)-250000)*0.05+MAX(0,MIN($B$5,1500000)-925000)*0.1+MAX(0,$B$5-1500000)*0.12)+IF($B$8="Additional / Investor",0.05*$B$5,0)+IF($B$9="Yes",0.02*$B$5,0))),IF($B$7="Scotland",((MAX(0,MIN($B$5,250000)-145000)*0.02+MAX(0,MIN($B$5,325000)-250000)*0.05+MAX(0,MIN($B$5,750000)-325000)*0.1+MAX(0,$B$5-750000)*0.12)-IF($B$8="First-time buyer",(IF($B$5>145000,MIN(600,0.02*(MIN($B$5,175000)-145000)),0)),0)+IF($B$8="Additional / Investor",0.08*$B$5,0)),IF($B$7="Wales",(IF($B$8="Additional / Investor",(MIN($B$5,180000)*0.05+MAX(0,MIN($B$5,250000)-180000)*0.085+MAX(0,MIN($B$5,400000)-250000)*0.1+MAX(0,MIN($B$5,750000)-400000)*0.125+MAX(0,MIN($B$5,1500000)-750000)*0.15+MAX(0,$B$5-1500000)*0.17),(MAX(0,MIN($B$5,400000)-225000)*0.06+MAX(0,MIN($B$5,750000)-400000)*0.075+MAX(0,MIN($B$5,1500000)-750000)*0.1+MAX(0,$B$5-1500000)*0.12))),0)))) -> 15000 | C13: Manual override (leave blank to use auto)
A14: Purchase legal fees | B14: 1500
A15: Survey / valuation | B15: 500
A16: Broker / sourcing fee | B16: 0
A17: Other acquisition costs | B17: 0
A19: FINANCE (OPTIONAL / BRIDGING STYLE)
A20: Loan-to-value (LTV) % | B20: 0.75
A21: Annual interest rate % | B21: 0.12
A22: Arrangement fee % (of total loan) | B22: 0.02
A23: Exit fee % (of total loan) | B23: 0.01
A24: Refurb financed? | B24: No
A25: Refurb loan % of total refurb (if financed) | B25: 0
A26: Average refurb drawdown factor (0–1) | B26: 0.5
A28: REFURB / VALUE-ADD
A29: Refurb budget | B29: 25000
A30: Contingency % | B30: 0.1
A31: Furniture / staging (capex) | B31: 0
A32: Professional fees (architect, etc.) | B32: 0
A33: Other works | B33: 0
A35: HOLDING COSTS (MONTHLY)
A36: Council tax + utilities + insurance / month | B36: 350
A37: Other holding costs / month | B37: 0
A39: SELLING COSTS
A40: Estate agent fee % (of sale price) | B40: 0.015
A41: Sale legal fees | B41: 1200
A42: EPC / certificates | B42: 0
A43: Marketing / staging (opex) | B43: 0
A44: Other sale costs | B44: 0
A46: TAX (OPTIONAL QUICK ESTIMATE)
A47: Apply tax estimate? | B47: No
...

Sheet Summary
A1: Summary (auto-calculated)
A2: Key outputs for your flip. Change Inputs → the results update.
A4: INPUTS (REFERENCE)
A5: Purchase price | B5: =Inputs!B5 -> 250000
A6: Sale price | B6: =Inputs!B6 -> 320000
A7: Location | B7: =Inputs!B7 -> England & N. Ireland
A8: Buyer type | B8: =Inputs!B8 -> Additional / Investor
A9: Duration (months) | B9: =Inputs!B10 -> 6
A10: Transaction tax | B10: =Inputs!B13 -> 15000
A12: COST BREAKDOWN
A13: Total acquisition (incl. tax) | B13: =(Inputs!B5)+(Inputs!B13)+(Inputs!B14)+(Inputs!B15)+(Inputs!B16)+(Inputs!B17) -> 267000
A14: Total refurb (incl. contingency) | B14: =(Inputs!B29)*(1+(Inputs!B30))+(Inputs!B31)+(Inputs!B32)+(Inputs!B33) -> 27500
A15: Total holding (monthly x months) | B15: =((Inputs!B36)+(Inputs!B37))*(Inputs!B10) -> 2100
A16: Total finance (interest + fees) | B16: =((((Inputs!B5)*(Inputs!B20))+(IF(Inputs!B24="Yes",(B14)*(Inputs!B25),0))*(Inputs!B26))*(Inputs!B21)*(Inputs!B10)/12)+((((Inputs!B5)*(Inputs!B20))+(IF(Inputs!B24="Yes",(B14)*(Inputs!B25),0)))*(Inputs!B22))+((((Inputs!B5)*(Inputs!B20))+(IF(Inputs!B24="Yes",(B14)*(Inputs!B25),0)))*(Inputs!B23)) -> 16875
A17: Total selling (incl. agent) | B17: =(Inputs!B6)*(Inputs!B40)+(Inputs!B41)+(Inputs!B42)+(Inputs!B43)+(Inputs!B44) -> 6000
A18: TOTAL COST | B18: =B13+B14+B15+B16+B17 -> 319475
A19: GROSS PROFIT (pre-tax) | B19: =(Inputs!B6)-B18 -> 525
A20: Profit margin | B20: =IF((Inputs!B6)=0,0,B19/(Inputs!B6)) -> 0.001640625
A21: Peak cash required (rough) | B21: =((Inputs!B5)*(1-(Inputs!B20)))+(Inputs!B13)+(Inputs!B14)+(Inputs!B15)+(Inputs!B16)+(Inputs!B17)+((B14)-(IF(Inputs!B24="Yes",(B14)*(Inputs!B25),0)))+B15+B16+(Inputs!B43) -> 125975
A22: ROI on cash (pre-tax) | B22: =IF(B21=0,0,B19/B21) -> 0.0041674936
A23: Annualised ROI (pre-tax) | B23: =IF((Inputs!B10)=0,0,(1+B22)^(12/(Inputs!B10))-1) -> 0.0083523551
A24: Break-even sale price | B24: =(B18-(Inputs!B6)*(Inputs!B40))/(1-(Inputs!B40)) -> 319467.01
A25: Post-tax profit (optional) | B25: =IF(Inputs!B47="Yes",B19*(1-(Inputs!B48)),B19) -> 525
A26: ROI on cash (post-tax) | B26: =IF(B21=0,0,B25/B21) -> 0.0041674936

Sheet Max Offer
A1: Max Offer Finder (target profit)
A2: Sets a target profit and searches a price range to find the highest purchase price that still meets it.
A4: Target profit (pre-tax) | B4: 20000 | C4: Max offer meeting target | D4: =IFERROR(LOOKUP(2,1/(B11:B210>= $B$4),A11:A210),"") -> 1095000
A5: Min offer price | B5: 100000
A6: Max offer price | B6: 600000
A7: Step | B7: 5000
A10: Offer price | B10: Profit (pre-tax)
A11: =$B$5+(0)*$B$7 -> 100000 | B11: =IF(A11>$B$6,"",(Inputs!B6)-((A11)+(IF(Inputs!D13<>"",Inputs!D13,IF(Inputs!B7="England & N. Ireland",(IF(Inputs!B8="First-time buyer",(IF(A11<=500000,MAX(0,A11-300000)*0.05,(MAX(0,MIN(A11,250000)-125000)*0.02+MAX(0,MIN(A11,925000)-250000)*0.05+MAX(0,MIN(A11,1500000)-925000)*0.1+MAX(0,A11-1500000)*0.12))),(MAX(0,MIN(A11,250000)-125000)*0.02+MAX(0,MIN(A11,925000)-250000)*0.05+MAX(0,MIN(A11,1500000)-925000)*0.1+MAX(0,A11-1500000)*0.12)+IF(Inputs!B8="Additional / Investor",0.05*A11,0)+IF(Inputs!B9="Yes",0.02*A11,0))),IF(Inputs!B7="Scotland",((MAX(0,MIN(A11,250000)-145000)*0.02+MAX(0,MIN(A11,325000)-250000)*0.05+MAX(0,MIN(A11,750000)-325000)*0.1+MAX(0,A11-750000)*0.12)-IF(Inputs!B8="First-time buyer",(IF(A11>145000,MIN(600,0.02*(MIN(A11,175000)-145000)),0)),0)+IF(Inputs!B8="Additional / Investor",0.08*A11,0)),IF(Inputs!B7="Wales",(IF(Inputs!B8="Additional / Investor",(MIN(A11,180000)*0.05+MAX(0,MIN(A11,250000)-180000)*0.085+MAX(0,MIN(A11,400000)-250000)*0.1+MAX(0,MIN(A11,750000)-400000)*0.125+MAX(0,MIN(A11,1500000)-750000)*0.15+MAX(0,A11-1500000)*0.17),(MAX(0,MIN(A11,400000)-225000)*0.06+MAX(0,MIN(A11,750000)-400000)*0.075+MAX(0,MIN(A11,1500000)-750000)*0.1+MAX(0,A11-1500000)*0.12))),0)))))+(Inputs!B14+Inputs!B15+Inputs!B16+Inputs!B17)+(Summary!B14)+(Summary!B15)+(((((A11)*Inputs!B20)+(IF(Inputs!B24="Yes",(Summary!B14)*Inputs!B25,0))*Inputs!B26)*Inputs!B21*Inputs!B10/12)+((((A11)*Inputs!B20)+(IF(Inputs!B24="Yes",(Summary!B14)*Inputs!B25,0)))*Inputs!B22)+((((A11)*Inputs!B20)+(IF(Inputs!B24="Yes",(Summary!B14)*Inputs!B25,0)))*Inputs!B23))+(Summary!B17))) -> 170650 | C11: =IF(A11>$B$6,"","")
A12: =$B$5+(1)*$B$7 -> 105000 | B12: =IF(A12>$B$6,"",(Inputs!B6)-((A12)+(IF(Inputs!D13<>"",Inputs!D13,IF(Inputs!B7="England & N. Ireland",(IF(Inputs!B8="First-time buyer",(IF(A12<=500000,MAX(0,A12-300000)*0.05,(MAX(0,MIN(A12,250000)-125000)*0.02+MAX(0,MIN(A12,925000)-250000)*0.05+MAX(0,MIN(A12,1500000)-925000)*0.1+MAX(0,A12-1500000)*0.12))),(MAX(0,MIN(A12,250000)-125000)*0.02+MAX(0,MIN(A12,925000)-250000)*0.05+MAX(0,MIN(A12,1500000)-925000)*0.1+MAX(0,A12-1500000)*0.12)+IF(Inputs!B8="Additional / Investor",0.05*A12,0)+IF(Inputs!B9="Yes",0.02*A12,0))),IF(Inputs!B7="Scotland",((MAX(0,MIN(A12,250000)-145000)*0.02+MAX(0,MIN(A12,325000)-250000)*0.05+MAX(0,MIN(A12,750000)-325000)*0.1+MAX(0,A12-750000)*0.12)-IF(Inputs!B8="First-time buyer",(IF(A12>145000,MIN(600,0.02*(MIN(A12,175000)-145000)),0)),0)+IF(Inputs!B8="Additional / Investor",0.08*A12,0)),IF(Inputs!B7="Wales",(IF(Inputs!B8="Additional / Investor",(MIN(A12,180000)*0.05+MAX(0,MIN(A12,250000)-180000)*0.085+MAX(0,MIN(A12,400000)-250000)*0.1+MAX(0,MIN(A12,750000)-400000)*0.125+MAX(0,MIN(A12,1500000)-750000)*0.15+MAX(0,A12-1500000)*0.17),(MAX(0,MIN(A12,400000)-225000)*0.06+MAX(0,MIN(A12,750000)-400000)*0.075+MAX(0,MIN(A12,1500000)-750000)*0.1+MAX(0,A12-1500000)*0.12))),0)))))+(Inputs!B14+Inputs!B15+Inputs!B16+Inputs!B17)+(Summary!B14)+(Summary!B15)+(((((A12)*Inputs!B20)+(IF(Inputs!B24="Yes",(Summary!B14)*Inputs!B25,0))*Inputs!B26)*Inputs!B21*Inputs!B10/12)+((((A12)*Inputs!B20)+(IF(Inputs!B24="Yes",(Summary!B14)*Inputs!B25,0)))*Inputs!B22)+((((A12)*Inputs!B20)+(IF(Inputs!B24="Yes",(Summary!B14)*Inputs!B25,0)))*Inputs!B23))+(Summary!B17))) -> 165062.5 | C12: =IF(A12>$B$6,"","")
A13: =$B$5+(2)*$B$7 -> 110000 | B13: =IF(A13>$B$6,"",(Inputs!B6)-((A13)+(IF(Inputs!D13<>"",Inputs!D13,IF(Inputs!B7="England & N. Ireland",(IF(Inputs!B8="First-time buyer",(IF(A13<=500000,MAX(0,A13-300000)*0.05,(MAX(0,MIN(A13,250000)-125000)*0.02+MAX(0,MIN(A13,925000)-250000)*0.05+MAX(0,MIN(A13,1500000)-925000)*0.1+MAX(0,A13-1500000)*0.12))),(MAX(0,MIN(A13,250000)-125000)*0.02+MAX(0,MIN(A13,925000)-250000)*0.05+MAX(0,MIN(A13,1500000)-925000)*0.1+MAX(0,A13-1500000)*0.12)+IF(Inputs!B8="Additional / Investor",0.05*A13,0)+IF(Inputs!B9="Yes",0.02*A13,0))),IF(Inputs!B7="Scotland",((MAX(0,MIN(A13,250000)-145000)*0.02+MAX(0,MIN(A13,325000)-250000)*0.05+MAX(0,MIN(A13,750000)-325000)*0.1+MAX(0,A13-750000)*0.12)-IF(Inputs!B8="First-time buyer",(IF(A13>145000,MIN(600,0.02*(MIN(A13,175000)-145000)),0)),0)+IF(Inputs!B8="Additional / Investor",0.08*A13,0)),IF(Inputs!B7="Wales",(IF(Inputs!B8="Additional / Investor",(MIN(A13,180000)*0.05+MAX(0,MIN(A13,250000)-180000)*0.085+MAX(0,MIN(A13,400000)-250000)*0.1+MAX(0,MIN(A13,750000)-400000)*0.125+MAX(0,MIN(A13,1500000)-750000)*0.15+MAX(0,A13-1500000)*0.17),(MAX(0,MIN(A13,400000)-225000)*0.06+MAX(0,MIN(A13,750000)-400000)*0.075+MAX(0,MIN(A13,1500000)-750000)*0.1+MAX(0,A13-1500000)*0.12))),0)))))+(Inputs!B14+Inputs!B15+Inputs!B16+Inputs!B17)+(Summary!B14)+(Summary!B15)+(((((A13)*Inputs!B20)+(IF(Inputs!B24="Yes",(Summary!B14)*Inputs!B25,0))*Inputs!B26)*Inputs!B21*Inputs!B10/12)+((((A13)*Inputs!B20)+(IF(Inputs!B24="Yes",(Summary!B14)*Inputs!B25,0)))*Inputs!B22)+((((A13)*Inputs!B20)+(IF(Inputs!B24="Yes",(Summary!B14)*Inputs!B25,0)))*Inputs!B23))+(Summary!B17))) -> 159475 | C13: =IF(A13>$B$6,"","")
A14: =$B$5+(3)*$B$7 -> 115000 | B14: =IF(A14>$B$6,"",(Inputs!B6)-((A14)+(IF(Inputs!D13<>"",Inputs!D13,IF(Inputs!B7="England & N. Ireland",(IF(Inputs!B8="First-time buyer",(IF(A14<=500000,MAX(0,A14-300000)*0.05,(MAX(0,MIN(A14,250000)-125000)*0.02+MAX(0,MIN(A14,925000)-250000)*0.05+MAX(0,MIN(A14,1500000)-925000)*0.1+MAX(0,A14-1500000)*0.12))),(MAX(0,MIN(A14,250000)-125000)*0.02+MAX(0,MIN(A14,925000)-250000)*0.05+MAX(0,MIN(A14,1500000)-925000)*0.1+MAX(0,A14-1500000)*0.12)+IF(Inputs!B8="Additional / Investor",0.05*A14,0)+IF(Inputs!B9="Yes",0.02*A14,0))),IF(Inputs!B7="Scotland",((MAX(0,MIN(A14,250000)-145000)*0.02+MAX(0,MIN(A14,325000)-250000)*0.05+MAX(0,MIN(A14,750000)-325000)*0.1+MAX(0,A14-750000)*0.12)-IF(Inputs!B8="First-time buyer",(IF(A14>145000,MIN(600,0.02*(MIN(A14,175000)-145000)),0)),0)+IF(Inputs!B8="Additional / Investor",0.08*A14,0)),IF(Inputs!B7="Wales",(IF(Inputs!B8="Additional / Investor",(MIN(A14,180000)*0.05+MAX(0,MIN(A14,250000)-180000)*0.085+MAX(0,MIN(A14,400000)-250000)*0.1+MAX(0,MIN(A14,750000)-400000)*0.125+MAX(0,MIN(A14,1500000)-750000)*0.15+MAX(0,A14-1500000)*0.17),(MAX(0,MIN(A14,400000)-225000)*0.06+MAX(0,MIN(A14,750000)-400000)*0.075+MAX(0,MIN(A14,1500000)-750000)*0.1+MAX(0,A14-1500000)*0.12))),0)))))+(Inputs!B14+Inputs!B15+Inputs!B16+Inputs!B17)+(Summary!B14)+(Summary!B15)+(((((A14)*Inputs!B20)+(IF(Inputs!B24="Yes",(Summary!B14)*Inputs!B25,0))*Inputs!B26)*Inputs!B21*Inputs!B10/12)+((((A14)*Inputs!B20)+(IF(Inputs!B24="Yes",(Summary!B14)*Inputs!B25,0)))*Inputs!B22)+((((A14)*Inputs!B20)+(IF(Inputs!B24="Yes",(Summary!B14)*Inputs!B25,0)))*Inputs!B23))+(Summary!B17))) -> 153887.5 | C14: =IF(A14>$B$6,"","")
A15: =$B$5+(4)*$B$7 -> 120000 | B15: =IF(A15>$B$6,"",(Inputs!B6)-((A15)+(IF(Inputs!D13<>"",Inputs!D13,IF(Inputs!B7="England & N. Ireland",(IF(Inputs!B8="First-time buyer",(IF(A15<=500000,MAX(0,A15-300000)*0.05,(MAX(0,MIN(A15,250000)-125000)*0.02+MAX(0,MIN(A15,925000)-250000)*0.05+MAX(0,MIN(A15,1500000)-925000)*0.1+MAX(0,A15-1500000)*0.12))),(MAX(0,MIN(A15,250000)-125000)*0.02+MAX(0,MIN(A15,925000)-250000)*0.05+MAX(0,MIN(A15,1500000)-925000)*0.1+MAX(0,A15-1500000)*0.12)+IF(Inputs!B8="Additional / Investor",0.05*A15,0)+IF(Inputs!B9="Yes",0.02*A15,0))),IF(Inputs!B7="Scotland",((MAX(0,MIN(A15,250000)-145000)*0.02+MAX(0,MIN(A15,325000)-250000)*0.05+MAX(0,MIN(A15,750000)-325000)*0.1+MAX(0,A15-750000)*0.12)-IF(Inputs!B8="First-time buyer",(IF(A15>145000,MIN(600,0.02*(MIN(A15,175000)-145000)),0)),0)+IF(Inputs!B8="Additional / Investor",0.08*A15,0)),IF(Inputs!B7="Wales",(IF(Inputs!B8="Additional / Investor",(MIN(A15,180000)*0.05+MAX(0,MIN(A15,250000)-180000)*0.085+MAX(0,MIN(A15,400000)-250000)*0.1+MAX(0,MIN(A15,750000)-400000)*0.125+MAX(0,MIN(A15,1500000)-750000)*0.15+MAX(0,A15-1500000)*0.17),(MAX(0,MIN(A15,400000)-225000)*0.06+MAX(0,MIN(A15,750000)-400000)*0.075+MAX(0,MIN(A15,1500000)-750000)*0.1+MAX(0,A15-1500000)*0.12))),0)))))+(Inputs!B14+Inputs!B15+Inputs!B16+Inputs!B17)+(Summary!B14)+(Summary!B15)+(((((A15)*Inputs!B20)+(IF(Inputs!B24="Yes",(Summary!B14)*Inputs!B25,0))*Inputs!B26)*Inputs!B21*Inputs!B10/12)+((((A15)*Inputs!B20)+(IF(Inputs!B24="Yes",(Summary!B14)*Inputs!B25,0)))*Inputs!B22)+((((A15)*Inputs!B20)+(IF(Inputs!B24="Yes",(Summary!B14)*Inputs!B25,0)))*Inputs!B23))+(Summary!B17))) -> 148300 | C15: =IF(A15>$B$6,"","")
A16: =$B$5+(5)*$B$7 -> 125000 | B16: =IF(A16>$B$6,"",(Inputs!B6)-((A16)+(IF(Inputs!D13<>"",Inputs!D13,IF(Inputs!B7="England & N. Ireland",(IF(Inputs!B8="First-time buyer",(IF(A16<=500000,MAX(0,A16-300000)*0.05,(MAX(0,MIN(A16,250000)-125000)*0.02+MAX(0,MIN(A16,925000)-250000)*0.05+MAX(0,MIN(A16,1500000)-925000)*0.1+MAX(0,A16-1500000)*0.12))),(MAX(0,MIN(A16,250000)-125000)*0.02+MAX(0,MIN(A16,925000)-250000)*0.05+MAX(0,MIN(A16,1500000)-925000)*0.1+MAX(0,A16-1500000)*0.12)+IF(Inputs!B8="Additional / Investor",0.05*A16,0)+IF(Inputs!B9="Yes",0.02*A16,0))),IF(Inputs!B7="Scotland",((MAX(0,MIN(A16,250000)-145000)*0.02+MAX(0,MIN(A16,325000)-250000)*0.05+MAX(0,MIN(A16,750000)-325000)*0.1+MAX(0,A16-750000)*0.12)-IF(Inputs!B8="First-time buyer",(IF(A16>145000,MIN(600,0.02*(MIN(A16,175000)-145000)),0)),0)+IF(Inputs!B8="Additional / Investor",0.08*A16,0)),IF(Inputs!B7="Wales",(IF(Inputs!B8="Additional / Investor",(MIN(A16,180000)*0.05+MAX(0,MIN(A16,250000)-180000)*0.085+MAX(0,MIN(A16,400000)-250000)*0.1+MAX(0,MIN(A16,750000)-400000)*0.125+MAX(0,MIN(A16,1500000)-750000)*0.15+MAX(0,A16-1500000)*0.17),(MAX(0,MIN(A16,400000)-225000)*0.06+MAX(0,MIN(A16,750000)-400000)*0.075+MAX(0,MIN(A16,1500000)-750000)*0.1+MAX(0,A16-1500000)*0.12))),0)))))+(Inputs!B14+Inputs!B15+Inputs!B16+Inputs!B17)+(Summary!B14)+(Summary!B15)+(((((A16)*Inputs!B20)+(IF(Inputs!B24="Yes",(Summary!B14)*Inputs!B25,0))*Inputs!B26)*Inputs!B21*Inputs!B10/12)+((((A16)*Inputs!B20)+(IF(Inputs!B24="Yes",(Summary!B14)*Inputs!B25,0)))*Inputs!B22)+((((A16)*Inputs!B20)+(IF(Inputs!B24="Yes",(Summary!B14)*Inputs!B25,0)))*Inputs!B23))+(Summary!B17))) -> 142712.5 | C16: =IF(A16>$B$6,"","")
A17: =$B$5+(6)*$B$7 -> 130000 | B17: =IF(A17>$B$6,"",(Inputs!B6)-((A17)+(IF(Inputs!D13<>"",Inputs!D13,IF(Inputs!B7="England & N. Ireland",(IF(Inputs!B8="First-time buyer",(IF(A17<=500000,MAX(0,A17-300000)*0.05,(MAX(0,MIN(A17,250000)-125000)*0.02+MAX(0,MIN(A17,925000)-250000)*0.05+MAX(0,MIN(A17,1500000)-925000)*0.1+MAX(0,A17-1500000)*0.12))),(MAX(0,MIN(A17,250000)-125000)*0.02+MAX(0,MIN(A17,925000)-250000)*0.05+MAX(0,MIN(A17,1500000)-925000)*0.1+MAX(0,A17-1500000)*0.12)+IF(Inputs!B8="Additional / Investor",0.05*A17,0)+IF(Inputs!B9="Yes",0.02*A17,0))),IF(Inputs!B7="Scotland",((MAX(0,MIN(A17,250000)-145000)*0.02+MAX(0,MIN(A17,325000)-250000)*0.05+MAX(0,MIN(A17,750000)-325000)*0.1+MAX(0,A17-750000)*0.12)-IF(Inputs!B8="First-time buyer",(IF(A17>145000,MIN(600,0.02*(MIN(A17,175000)-145000)),0)),0)+IF(Inputs!B8="Additional / Investor",0.08*A17,0)),IF(Inputs!B7="Wales",(IF(Inputs!B8="Additional / Investor",(MIN(A17,180000)*0.05+MAX(0,MIN(A17,250000)-180000)*0.085+MAX(0,MIN(A17,400000)-250000)*0.1+MAX(0,MIN(A17,750000)-400000)*0.125+MAX(0,MIN(A17,1500000)-750000)*0.15+MAX(0,A17-1500000)*0.17),(MAX(0,MIN(A17,400000)-225000)*0.06+MAX(0,MIN(A17,750000)-400000)*0.075+MAX(0,MIN(A17,1500000)-750000)*0.1+MAX(0,A17-1500000)*0.12))),0)))))+(Inputs!B14+Inputs!B15+Inputs!B16+Inputs!B17)+(Summary!B14)+(Summary!B15)+(((((A17)*Inputs!B20)+(IF(Inputs!B24="Yes",(Summary!B14)*Inputs!B25,0))*Inputs!B26)*Inputs!B21*Inputs!B10/12)+((((A17)*Inputs!B20)+(IF(Inputs!B24="Yes",(Summary!B14)*Inputs!B25,0)))*Inputs!B22)+((((A17)*Inputs!B20)+(IF(Inputs!B24="Yes",(Summary!B14)*Inputs!B25,0)))*Inputs!B23))+(Summary!B17))) -> 137025 | C17: =IF(A17>$B$6,"","")
A18: =$B$5+(7)*$B$7 -> 135000 | B18: =IF(A18>$B$6,"",(Inputs!B6)-((A18)+(IF(Inputs!D13<>"",Inputs!D13,IF(Inputs!B7="England & N. Ireland",(IF(Inputs!B8="First-time buyer",(IF(A18<=500000,MAX(0,A18-300000)*0.05,(MAX(0,MIN(A18,250000)-125000)*0.02+MAX(0,MIN(A18,925000)-250000)*0.05+MAX(0,MIN(A18,1500000)-925000)*0.1+MAX(0,A18-1500000)*0.12))),(MAX(0,MIN(A18,250000)-125000)*0.02+MAX(0,MIN(A18,925000)-250000)*0.05+MAX(0,MIN(A18,1500000)-925000)*0.1+MAX(0,A18-1500000)*0.12)+IF(Inputs!B8="Additional / Investor",0.05*A18,0)+IF(Inputs!B9="Yes",0.02*A18,0))),IF(Inputs!B7="Scotland",((MAX(0,MIN(A18,250000)-145000)*0.02+MAX(0,MIN(A18,325000)-250000)*0.05+MAX(0,MIN(A18,750000)-325000)*0.1+MAX(0,A18-750000)*0.12)-IF(Inputs!B8="First-time buyer",(IF(A18>145000,MIN(600,0.02*(MIN(A18,175000)-145000)),0)),0)+IF(Inputs!B8="Additional / Investor",0.08*A18,0)),IF(Inputs!B7="Wales",(IF(Inputs!B8="Additional / Investor",(MIN(A18,180000)*0.05+MAX(0,MIN(A18,250000)-180000)*0.085+MAX(0,MIN(A18,400000)-250000)*0.1+MAX(0,MIN(A18,750000)-400000)*0.125+MAX(0,MIN(A18,1500000)-750000)*0.15+MAX(0,A18-1500000)*0.17),(MAX(0,MIN(A18,400000)-225000)*0.06+MAX(0,MIN(A18,750000)-400000)*0.075+MAX(0,MIN(A18,1500000)-750000)*0.1+MAX(0,A18-1500000)*0.12))),0)))))+(Inputs!B14+Inputs!B15+Inputs!B16+Inputs!B17)+(Summary!B14)+(Summary!B15)+(((((A18)*Inputs!B20)+(IF(Inputs!B24="Yes",(Summary!B14)*Inputs!B25,0))*Inputs!B26)*Inputs!B21*Inputs!B10/12)+((((A18)*Inputs!B20)+(IF(Inputs!B24="Yes",(Summary!B14)*Inputs!B25,0)))*Inputs!B22)+((((A18)*Inputs!B20)+(IF(Inputs!B24="Yes",(Summary!B14)*Inputs!B25,0)))*Inputs!B23))+(Summary!B17))) -> 131337.5 | C18: =IF(A18>$B$6,"","")
A19: =$B$5+(8)*$B$7 -> 140000 | B19: =IF(A19>$B$6,"",(Inputs!B6)-((A19)+(IF(Inputs!D13<>"",Inputs!D13,IF(Inputs!B7="England & N. Ireland",(IF(Inputs!B8="First-time buyer",(IF(A19<=500000,MAX(0,A19-300000)*0.05,(MAX(0,MIN(A19,250000)-125000)*0.02+MAX(0,MIN(A19,925000)-250000)*0.05+MAX(0,MIN(A19,1500000)-925000)*0.1+MAX(0,A19-1500000)*0.12))),(MAX(0,MIN(A19,250000)-125000)*0.02+MAX(0,MIN(A19,925000)-250000)*0.05+MAX(0,MIN(A19,1500000)-925000)*0.1+MAX(0,A19-1500000)*0.12)+IF(Inputs!B8="Additional / Investor",0.05*A19,0)+IF(Inputs!B9="Yes",0.02*A19,0))),IF(Inputs!B7="Scotland",((MAX(0,MIN(A19,250000)-145000)*0.02+MAX(0,MIN(A19,325000)-250000)*0.05+MAX(0,MIN(A19,750000)-325000)*0.1+MAX(0,A19-750000)*0.12)-IF(Inputs!B8="First-time buyer",(IF(A19>145000,MIN(600,0.02*(MIN(A19,175000)-145000)),0)),0)+IF(Inputs!B8="Additional / Investor",0.08*A19,0)),IF(Inputs!B7="Wales",(IF(Inputs!B8="Additional / Investor",(MIN(A19,180000)*0.05+MAX(0,MIN(A19,250000)-180000)*0.085+MAX(0,MIN(A19,400000)-250000)*0.1+MAX(0,MIN(A19,750000)-400000)*0.125+MAX(0,MIN(A19,1500000)-750000)*0.15+MAX(0,A19-1500000)*0.17),(MAX(0,MIN(A19,400000)-225000)*0.06+MAX(0,MIN(A19,750000)-400000)*0.075+MAX(0,MIN(A19,1500000)-750000)*0.1+MAX(0,A19-1500000)*0.12))),0)))))+(Inputs!B14+Inputs!B15+Inputs!B16+Inputs!B17)+(Summary!B14)+(Summary!B15)+(((((A19)*Inputs!B20)+(IF(Inputs!B24="Yes",(Summary!B14)*Inputs!B25,0))*Inputs!B26)*Inputs!B21*Inputs!B10/12)+((((A19)*Inputs!B20)+(IF(Inputs!B24="Yes",(Summary!B14)*Inputs!B25,0)))*Inputs!B22)+((((A19)*Inputs!B20)+(IF(Inputs!B24="Yes",(Summary!B14)*Inputs!B25,0)))*Inputs!B23))+(Summary!B17))) -> 125650 | C19: =IF(A19>$B$6,"","")
A20: =$B$5+(9)*$B$7 -> 145000 | B20: =IF(A20>$B$6,"",(Inputs!B6)-((A20)+(IF(Inputs!D13<>"",Inputs!D13,IF(Inputs!B7="England & N. Ireland",(IF(Inputs!B8="First-time buyer",(IF(A20<=500000,MAX(0,A20-300000)*0.05,(MAX(0,MIN(A20,250000)-125000)*0.02+MAX(0,MIN(A20,925000)-250000)*0.05+MAX(0,MIN(A20,1500000)-925000)*0.1+MAX(0,A20-1500000)*0.12))),(MAX(0,MIN(A20,250000)-125000)*0.02+MAX(0,MIN(A20,925000)-250000)*0.05+MAX(0,MIN(A20,1500000)-925000)*0.1+MAX(0,A20-1500000)*0.12)+IF(Inputs!B8="Additional / Investor",0.05*A20,0)+IF(Inputs!B9="Yes",0.02*A20,0))),IF(Inputs!B7="Scotland",((MAX(0,MIN(A20,250000)-145000)*0.02+MAX(0,MIN(A20,325000)-250000)*0.05+MAX(0,MIN(A20,750000)-325000)*0.1+MAX(0,A20-750000)*0.12)-IF(Inputs!B8="First-time buyer",(IF(A20>145000,MIN(600,0.02*(MIN(A20,175000)-145000)),0)),0)+IF(Inputs!B8="Additional / Investor",0.08*A20,0)),IF(Inputs!B7="Wales",(IF(Inputs!B8="Additional / Investor",(MIN(A20,180000)*0.05+MAX(0,MIN(A20,250000)-180000)*0.085+MAX(0,MIN(A20,400000)-250000)*0.1+MAX(0,MIN(A20,750000)-400000)*0.125+MAX(0,MIN(A20,1500000)-750000)*0.15+MAX(0,A20-1500000)*0.17),(MAX(0,MIN(A20,400000)-225000)*0.06+MAX(0,MIN(A20,750000)-400000)*0.075+MAX(0,MIN(A20,1500000)-750000)*0.1+MAX(0,A20-1500000)*0.12))),0)))))+(Inputs!B14+Inputs!B15+Inputs!B16+Inputs!B17)+(Summary!B14)+(Summary!B15)+(((((A20)*Inputs!B20)+(IF(Inputs!B24="Yes",(Summary!B14)*Inputs!B25,0))*Inputs!B26)*Inputs!B21*Inputs!B10/12)+((((A20)*Inputs!B20)+(IF(Inputs!B24="Yes",(Summary!B14)*Inputs!B25,0)))*Inputs!B22)+((((A20)*Inputs!B20)+(IF(Inputs!B24="Yes",(Summary!B14)*Inputs!B25,0)))*Inputs!B23))+(Summary!B17))) -> 119962.5 | C20: =IF(A20>$B$6,"","")
A21: =$B$5+(10)*$B$7 -> 150000 | B21: =IF(A21>$B$6,"",(Inputs!B6)-((A21)+(IF(Inputs!D13<>"",Inputs!D13,IF(Inputs!B7="England & N. Ireland",(IF(Inputs!B8="First-time buyer",(IF(A21<=500000,MAX(0,A21-300000)*0.05,(MAX(0,MIN(A21,250000)-125000)*0.02+MAX(0,MIN(A21,925000)-250000)*0.05+MAX(0,MIN(A21,1500000)-925000)*0.1+MAX(0,A21-1500000)*0.12))),(MAX(0,MIN(A21,250000)-125000)*0.02+MAX(0,MIN(A21,925000)-250000)*0.05+MAX(0,MIN(A21,1500000)-925000)*0.1+MAX(0,A21-1500000)*0.12)+IF(Inputs!B8="Additional / Investor",0.05*A21,0)+IF(Inputs!B9="Yes",0.02*A21,0))),IF(Inputs!B7="Scotland",((MAX(0,MIN(A21,250000)-145000)*0.02+MAX(0,MIN(A21,325000)-250000)*0.05+MAX(0,MIN(A21,750000)-325000)*0.1+MAX(0,A21-750000)*0.12)-IF(Inputs!B8="First-time buyer",(IF(A21>145000,MIN(600,0.02*(MIN(A21,175000)-145000)),0)),0)+IF(Inputs!B8="Additional / Investor",0.08*A21,0)),IF(Inputs!B7="Wales",(IF(Inputs!B8="Additional / Investor",(MIN(A21,180000)*0.05+MAX(0,MIN(A21,250000)-180000)*0.085+MAX(0,MIN(A21,400000)-250000)*0.1+MAX(0,MIN(A21,750000)-400000)*0.125+MAX(0,MIN(A21,1500000)-750000)*0.15+MAX(0,A21-1500000)*0.17),(MAX(0,MIN(A21,400000)-225000)*0.06+MAX(0,MIN(A21,750000)-400000)*0.075+MAX(0,MIN(A21,1500000)-750000)*0.1+MAX(0,A21-1500000)*0.12))),0)))))+(Inputs!B14+Inputs!B15+Inputs!B16+Inputs!B17)+(Summary!B14)+(Summary!B15)+(((((A21)*Inputs!B20)+(IF(Inputs!B24="Yes",(Summary!B14)*Inputs!B25,0))*Inputs!B26)*Inputs!B21*Inputs!B10/12)+((((A21)*Inputs!B20)+(IF(Inputs!B24="Yes",(Summary!B14)*Inputs!B25,0)))*Inputs!B22)+((((A21)*Inputs!B20)+(IF(Inputs!B24="Yes",(Summary!B14)*Inputs!B25,0)))*Inputs!B23))+(Summary!B17))) -> 114275 | C21: =IF(A21>$B$6,"","")
A22: =$B$5+(11)*$B$7 -> 155000 | B22: =IF(A22>$B$6,"",(Inputs!B6)-((A22)+(IF(Inputs!D13<>"",Inputs!D13,IF(Inputs!B7="England & N. Ireland",(IF(Inputs!B8="First-time buyer",(IF(A22<=500000,MAX(0,A22-300000)*0.05,(MAX(0,MIN(A22,250000)-125000)*0.02+MAX(0,MIN(A22,925000)-250000)*0.05+MAX(0,MIN(A22,1500000)-925000)*0.1+MAX(0,A22-1500000)*0.12))),(MAX(0,MIN(A22,250000)-125000)*0.02+MAX(0,MIN(A22,925000)-250000)*0.05+MAX(0,MIN(A22,1500000)-925000)*0.1+MAX(0,A22-1500000)*0.12)+IF(Inputs!B8="Additional / Investor",0.05*A22,0)+IF(Inputs!B9="Yes",0.02*A22,0))),IF(Inputs!B7="Scotland",((MAX(0,MIN(A22,250000)-145000)*0.02+MAX(0,MIN(A22,325000)-250000)*0.05+MAX(0,MIN(A22,750000)-325000)*0.1+MAX(0,A22-750000)*0.12)-IF(Inputs!B8="First-time buyer",(IF(A22>145000,MIN(600,0.02*(MIN(A22,175000)-145000)),0)),0)+IF(Inputs!B8="Additional / Investor",0.08*A22,0)),IF(Inputs!B7="Wales",(IF(Inputs!B8="Additional / Investor",(MIN(A22,180000)*0.05+MAX(0,MIN(A22,250000)-180000)*0.085+MAX(0,MIN(A22,400000)-250000)*0.1+MAX(0,MIN(A22,750000)-400000)*0.125+MAX(0,MIN(A22,1500000)-750000)*0.15+MAX(0,A22-1500000)*0.17),(MAX(0,MIN(A22,400000)-225000)*0.06+MAX(0,MIN(A22,750000)-400000)*0.075+MAX(0,MIN(A22,1500000)-750000)*0.1+MAX(0,A22-1500000)*0.12))),0)))))+(Inputs!B14+Inputs!B15+Inputs!B16+Inputs!B17)+(Summary!B14)+(Summary!B15)+(((((A22)*Inputs!B20)+(IF(Inputs!B24="Yes",(Summary!B14)*Inputs!B25,0))*Inputs!B26)*Inputs!B21*Inputs!B10/12)+((((A22)*Inputs!B20)+(IF(Inputs!B24="Yes",(Summary!B14)*Inputs!B25,0)))*Inputs!B22)+((((A22)*Inputs!B20)+(IF(Inputs!B24="Yes",(Summary!B14)*Inputs!B25,0)))*Inputs!B23))+(Summary!B17))) -> 108587.5 | C22: =IF(A22>$B$6,"","")
A23: =$B$5+(12)*$B$7 -> 160000 | B23: =IF(A23>$B$6,"",(Inputs!B6)-((A23)+(IF(Inputs!D13<>"",Inputs!D13,IF(Inputs!B7="England & N. Ireland",(IF(Inputs!B8="First-time buyer",(IF(A23<=500000,MAX(0,A23-300000)*0.05,(MAX(0,MIN(A23,250000)-125000)*0.02+MAX(0,MIN(A23,925000)-250000)*0.05+MAX(0,MIN(A23,1500000)-925000)*0.1+MAX(0,A23-1500000)*0.12))),(MAX(0,MIN(A23,250000)-125000)*0.02+MAX(0,MIN(A23,925000)-250000)*0.05+MAX(0,MIN(A23,1500000)-925000)*0.1+MAX(0,A23-1500000)*0.12)+IF(Inputs!B8="Additional / Investor",0.05*A23,0)+IF(Inputs!B9="Yes",0.02*A23,0))),IF(Inputs!B7="Scotland",((MAX(0,MIN(A23,250000)-145000)*0.02+MAX(0,MIN(A23,325000)-250000)*0.05+MAX(0,MIN(A23,750000)-325000)*0.1+MAX(0,A23-750000)*0.12)-IF(Inputs!B8="First-time buyer",(IF(A23>145000,MIN(600,0.02*(MIN(A23,175000)-145000)),0)),0)+IF(Inputs!B8="Additional / Investor",0.08*A23,0)),IF(Inputs!B7="Wales",(IF(Inputs!B8="Additional / Investor",(MIN(A23,180000)*0.05+MAX(0,MIN(A23,250000)-180000)*0.085+MAX(0,MIN(A23,400000)-250000)*0.1+MAX(0,MIN(A23,750000)-400000)*0.125+MAX(0,MIN(A23,1500000)-750000)*0.15+MAX(0,A23-1500000)*0.17),(MAX(0,MIN(A23,400000)-225000)*0.06+MAX(0,MIN(A23,750000)-400000)*0.075+MAX(0,MIN(A23,1500000)-750000)*0.1+MAX(0,A23-1500000)*0.12))),0)))))+(Inputs!B14+Inputs!B15+Inputs!B16+Inputs!B17)+(Summary!B14)+(Summary!B15)+(((((A23)*Inputs!B20)+(IF(Inputs!B24="Yes",(Summary!B14)*Inputs!B25,0))*Inputs!B26)*Inputs!B21*Inputs!B10/12)+((((A23)*Inputs!B20)+(IF(Inputs!B24="Yes",(Summary!B14)*Inputs!B25,0)))*Inputs!B22)+((((A23)*Inputs!B20)+(IF(Inputs!B24="Yes",(Summary!B14)*Inputs!B25,0)))*Inputs!B23))+(Summary!B17))) -> 102900 | C23: =IF(A23>$B$6,"","")
A24: =$B$5+(13)*$B$7 -> 165000 | B24: =IF(A24>$B$6,"",(Inputs!B6)-((A24)+(IF(Inputs!D13<>"",Inputs!D13,IF(Inputs!B7="England & N. Ireland",(IF(Inputs!B8="First-time buyer",(IF(A24<=500000,MAX(0,A24-300000)*0.05,(MAX(0,MIN(A24,250000)-125000)*0.02+MAX(0,MIN(A24,925000)-250000)*0.05+MAX(0,MIN(A24,1500000)-925000)*0.1+MAX(0,A24-1500000)*0.12))),(MAX(0,MIN(A24,250000)-125000)*0.02+MAX(0,MIN(A24,925000)-250000)*0.05+MAX(0,MIN(A24,1500000)-925000)*0.1+MAX(0,A24-1500000)*0.12)+IF(Inputs!B8="Additional / Investor",0.05*A24,0)+IF(Inputs!B9="Yes",0.02*A24,0))),IF(Inputs!B7="Scotland",((MAX(0,MIN(A24,250000)-145000)*0.02+MAX(0,MIN(A24,325000)-250000)*0.05+MAX(0,MIN(A24,750000)-325000)*0.1+MAX(0,A24-750000)*0.12)-IF(Inputs!B8="First-time buyer",(IF(A24>145000,MIN(600,0.02*(MIN(A24,175000)-145000)),0)),0)+IF(Inputs!B8="Additional / Investor",0.08*A24,0)),IF(Inputs!B7="Wales",(IF(Inputs!B8="Additional / Investor",(MIN(A24,180000)*0.05+MAX(0,MIN(A24,250000)-180000)*0.085+MAX(0,MIN(A24,400000)-250000)*0.1+MAX(0,MIN(A24,750000)-400000)*0.125+MAX(0,MIN(A24,1500000)-750000)*0.15+MAX(0,A24-1500000)*0.17),(MAX(0,MIN(A24,400000)-225000)*0.06+MAX(0,MIN(A24,750000)-400000)*0.075+MAX(0,MIN(A24,1500000)-750000)*0.1+MAX(0,A24-1500000)*0.12))),0)))))+(Inputs!B14+Inputs!B15+Inputs!B16+Inputs!B17)+(Summary!B14)+(Summary!B15)+(((((A24)*Inputs!B20)+(IF(Inputs!B24="Yes",(Summary!B14)*Inputs!B25,0))*Inputs!B26)*Inputs!B21*Inputs!B10/12)+((((A24)*Inputs!B20)+(IF(Inputs!B24="Yes",(Summary!B14)*Inputs!B25,0)))*Inputs!B22)+((((A24)*Inputs!B20)+(IF(Inputs!B24="Yes",(Summary!B14)*Inputs!B25,0)))*Inputs!B23))+(Summary!B17))) -> 97212.5 | C24: =IF(A24>$B$6,"","")
A25: =$B$5+(14)*$B$7 -> 170000 | B25: =IF(A25>$B$6,"",(Inputs!B6)-((A25)+(IF(Inputs!D13<>"",Inputs!D13,IF(Inputs!B7="England & N. Ireland",(IF(Inputs!B8="First-time buyer",(IF(A25<=500000,MAX(0,A25-300000)*0.05,(MAX(0,MIN(A25,250000)-125000)*0.02+MAX(0,MIN(A25,925000)-250000)*0.05+MAX(0,MIN(A25,1500000)-925000)*0.1+MAX(0,A25-1500000)*0.12))),(MAX(0,MIN(A25,250000)-125000)*0.02+MAX(0,MIN(A25,925000)-250000)*0.05+MAX(0,MIN(A25,1500000)-925000)*0.1+MAX(0,A25-1500000)*0.12)+IF(Inputs!B8="Additional / Investor",0.05*A25,0)+IF(Inputs!B9="Yes",0.02*A25,0))),IF(Inputs!B7="Scotland",((MAX(0,MIN(A25,250000)-145000)*0.02+MAX(0,MIN(A25,325000)-250000)*0.05+MAX(0,MIN(A25,750000)-325000)*0.1+MAX(0,A25-750000)*0.12)-IF(Inputs!B8="First-time buyer",(IF(A25>145000,MIN(600,0.02*(MIN(A25,175000)-145000)),0)),0)+IF(Inputs!B8="Additional / Investor",0.08*A25,0)),IF(Inputs!B7="Wales",(IF(Inputs!B8="Additional / Investor",(MIN(A25,180000)*0.05+MAX(0,MIN(A25,250000)-180000)*0.085+MAX(0,MIN(A25,400000)-250000)*0.1+MAX(0,MIN(A25,750000)-400000)*0.125+MAX(0,MIN(A25,1500000)-750000)*0.15+MAX(0,A25-1500000)*0.17),(MAX(0,MIN(A25,400000)-225000)*0.06+MAX(0,MIN(A25,750000)-400000)*0.075+MAX(0,MIN(A25,1500000)-750000)*0.1+MAX(0,A25-1500000)*0.12))),0)))))+(Inputs!B14+Inputs!B15+Inputs!B16+Inputs!B17)+(Summary!B14)+(Summary!B15)+(((((A25)*Inputs!B20)+(IF(Inputs!B24="Yes",(Summary!B14)*Inputs!B25,0))*Inputs!B26)*Inputs!B21*Inputs!B10/12)+((((A25)*Inputs!B20)+(IF(Inputs!B24="Yes",(Summary!B14)*Inputs!B25,0)))*Inputs!B22)+((((A25)*Inputs!B20)+(IF(Inputs!B24="Yes",(Summary!B14)*Inputs!B25,0)))*Inputs!B23))+(Summary!B17))) -> 91525 | C25: =IF(A25>$B$6,"","")
A26: =$B$5+(15)*$B$7 -> 175000 | B26: =IF(A26>$B$6,"",(Inputs!B6)-((A26)+(IF(Inputs!D13<>"",Inputs!D13,IF(Inputs!B7="England & N. Ireland",(IF(Inputs!B8="First-time buyer",(IF(A26<=500000,MAX(0,A26-300000)*0.05,(MAX(0,MIN(A26,250000)-125000)*0.02+MAX(0,MIN(A26,925000)-250000)*0.05+MAX(0,MIN(A26,1500000)-925000)*0.1+MAX(0,A26-1500000)*0.12))),(MAX(0,MIN(A26,250000)-125000)*0.02+MAX(0,MIN(A26,925000)-250000)*0.05+MAX(0,MIN(A26,1500000)-925000)*0.1+MAX(0,A26-1500000)*0.12)+IF(Inputs!B8="Additional / Investor",0.05*A26,0)+IF(Inputs!B9="Yes",0.02*A26,0))),IF(Inputs!B7="Scotland",((MAX(0,MIN(A26,250000)-145000)*0.02+MAX(0,MIN(A26,325000)-250000)*0.05+MAX(0,MIN(A26,750000)-325000)*0.1+MAX(0,A26-750000)*0.12)-IF(Inputs!B8="First-time buyer",(IF(A26>145000,MIN(600,0.02*(MIN(A26,175000)-145000)),0)),0)+IF(Inputs!B8="Additional / Investor",0.08*A26,0)),IF(Inputs!B7="Wales",(IF(Inputs!B8="Additional / Investor",(MIN(A26,180000)*0.05+MAX(0,MIN(A26,250000)-180000)*0.085+MAX(0,MIN(A26,400000)-250000)*0.1+MAX(0,MIN(A26,750000)-400000)*0.125+MAX(0,MIN(A26,1500000)-750000)*0.15+MAX(0,A26-1500000)*0.17),(MAX(0,MIN(A26,400000)-225000)*0.06+MAX(0,MIN(A26,750000)-400000)*0.075+MAX(0,MIN(A26,1500000)-750000)*0.1+MAX(0,A26-1500000)*0.12))),0)))))+(Inputs!B14+Inputs!B15+Inputs!B16+Inputs!B17)+(Summary!B14)+(Summary!B15)+(((((A26)*Inputs!B20)+(IF(Inputs!B24="Yes",(Summary!B14)*Inputs!B25,0))*Inputs!B26)*Inputs!B21*Inputs!B10/12)+((((A26)*Inputs!B20)+(IF(Inputs!B24="Yes",(Summary!B14)*Inputs!B25,0)))*Inputs!B22)+((((A26)*Inputs!B20)+(IF(Inputs!B24="Yes",(Summary!B14)*Inputs!B25,0)))*Inputs!B23))+(Summary!B17))) -> 85837.5 | C26: =IF(A26>$B$6,"","")
A27: =$B$5+(16)*$B$7 -> 180000 | B27: =IF(A27>$B$6,"",(Inputs!B6)-((A27)+(IF(Inputs!D13<>"",Inputs!D13,IF(Inputs!B7="England & N. Ireland",(IF(Inputs!B8="First-time buyer",(IF(A27<=500000,MAX(0,A27-300000)*0.05,(MAX(0,MIN(A27,250000)-125000)*0.02+MAX(0,MIN(A27,925000)-250000)*0.05+MAX(0,MIN(A27,1500000)-925000)*0.1+MAX(0,A27-1500000)*0.12))),(MAX(0,MIN(A27,250000)-125000)*0.02+MAX(0,MIN(A27,925000)-250000)*0.05+MAX(0,MIN(A27,1500000)-925000)*0.1+MAX(0,A27-1500000)*0.12)+IF(Inputs!B8="Additional / Investor",0.05*A27,0)+IF(Inputs!B9="Yes",0.02*A27,0))),IF(Inputs!B7="Scotland",((MAX(0,MIN(A27,250000)-145000)*0.02+MAX(0,MIN(A27,325000)-250000)*0.05+MAX(0,MIN(A27,750000)-325000)*0.1+MAX(0,A27-750000)*0.12)-IF(Inputs!B8="First-time buyer",(IF(A27>145000,MIN(600,0.02*(MIN(A27,175000)-145000)),0)),0)+IF(Inputs!B8="Additional / Investor",0.08*A27,0)),IF(Inputs!B7="Wales",(IF(Inputs!B8="Additional / Investor",(MIN(A27,180000)*0.05+MAX(0,MIN(A27,250000)-180000)*0.085+MAX(0,MIN(A27,400000)-250000)*0.1+MAX(0,MIN(A27,750000)-400000)*0.125+MAX(0,MIN(A27,1500000)-750000)*0.15+MAX(0,A27-1500000)*0.17),(MAX(0,MIN(A27,400000)-225000)*0.06+MAX(0,MIN(A27,750000)-400000)*0.075+MAX(0,MIN(A27,1500000)-750000)*0.1+MAX(0,A27-1500000)*0.12))),0)))))+(Inputs!B14+Inputs!B15+Inputs!B16+Inputs!B17)+(Summary!B14)+(Summary!B15)+(((((A27)*Inputs!B20)+(IF(Inputs!B24="Yes",(Summary!B14)*Inputs!B25,0))*Inputs!B26)*Inputs!B21*Inputs!B10/12)+((((A27)*Inputs!B20)+(IF(Inputs!B24="Yes",(Summary!B14)*Inputs!B25,0)))*Inputs!B22)+((((A27)*Inputs!B20)+(IF(Inputs!B24="Yes",(Summary!B14)*Inputs!B25,0)))*Inputs!B23))+(Summary!B17))) -> 80150 | C27: =IF(A27>$B$6,"","")
A28: =$B$5+(17)*$B$7 -> 185000 | B28: =IF(A28>$B$6,"",(Inputs!B6)-((A28)+(IF(Inputs!D13<>"",Inputs!D13,IF(Inputs!B7="England & N. Ireland",(IF(Inputs!B8="First-time buyer",(IF(A28<=500000,MAX(0,A28-300000)*0.05,(MAX(0,MIN(A28,250000)-125000)*0.02+MAX(0,MIN(A28,925000)-250000)*0.05+MAX(0,MIN(A28,1500000)-925000)*0.1+MAX(0,A28-1500000)*0.12))),(MAX(0,MIN(A28,250000)-125000)*0.02+MAX(0,MIN(A28,925000)-250000)*0.05+MAX(0,MIN(A28,1500000)-925000)*0.1+MAX(0,A28-1500000)*0.12)+IF(Inputs!B8="Additional / Investor",0.05*A28,0)+IF(Inputs!B9="Yes",0.02*A28,0))),IF(Inputs!B7="Scotland",((MAX(0,MIN(A28,250000)-145000)*0.02+MAX(0,MIN(A28,325000)-250000)*0.05+MAX(0,MIN(A28,750000)-325000)*0.1+MAX(0,A28-750000)*0.12)-IF(Inputs!B8="First-time buyer",(IF(A28>145000,MIN(600,0.02*(MIN(A28,175000)-145000)),0)),0)+IF(Inputs!B8="Additional / Investor",0.08*A28,0)),IF(Inputs!B7="Wales",(IF(Inputs!B8="Additional / Investor",(MIN(A28,180000)*0.05+MAX(0,MIN(A28,250000)-180000)*0.085+MAX(0,MIN(A28,400000)-250000)*0.1+MAX(0,MIN(A28,750000)-400000)*0.125+MAX(0,MIN(A28,1500000)-750000)*0.15+MAX(0,A28-1500000)*0.17),(MAX(0,MIN(A28,400000)-225000)*0.06+MAX(0,MIN(A28,750000)-400000)*0.075+MAX(0,MIN(A28,1500000)-750000)*0.1+MAX(0,A28-1500000)*0.12))),0)))))+(Inputs!B14+Inputs!B15+Inputs!B16+Inputs!B17)+(Summary!B14)+(Summary!B15)+(((((A28)*Inputs!B20)+(IF(Inputs!B24="Yes",(Summary!B14)*Inputs!B25,0))*Inputs!B26)*Inputs!B21*Inputs!B10/12)+((((A28)*Inputs!B20)+(IF(Inputs!B24="Yes",(Summary!B14)*Inputs!B25,0)))*Inputs!B22)+((((A28)*Inputs!B20)+(IF(Inputs!B24="Yes",(Summary!B14)*Inputs!B25,0)))*Inputs!B23))+(Summary!B17))) -> 74462.5 | C28: =IF(A28>$B$6,"","")
A29: =$B$5+(18)*$B$7 -> 190000 | B29: =IF(A29>$B$6,"",(Inputs!B6)-((A29)+(IF(Inputs!D13<>"",Inputs!D13,IF(Inputs!B7="England & N. Ireland",(IF(Inputs!B8="First-time buyer",(IF(A29<=500000,MAX(0,A29-300000)*0.05,(MAX(0,MIN(A29,250000)-125000)*0.02+MAX(0,MIN(A29,925000)-250000)*0.05+MAX(0,MIN(A29,1500000)-925000)*0.1+MAX(0,A29-1500000)*0.12))),(MAX(0,MIN(A29,250000)-125000)*0.02+MAX(0,MIN(A29,925000)-250000)*0.05+MAX(0,MIN(A29,1500000)-925000)*0.1+MAX(0,A29-1500000)*0.12)+IF(Inputs!B8="Additional / Investor",0.05*A29,0)+IF(Inputs!B9="Yes",0.02*A29,0))),IF(Inputs!B7="Scotland",((MAX(0,MIN(A29,250000)-145000)*0.02+MAX(0,MIN(A29,325000)-250000)*0.05+MAX(0,MIN(A29,750000)-325000)*0.1+MAX(0,A29-750000)*0.12)-IF(Inputs!B8="First-time buyer",(IF(A29>145000,MIN(600,0.02*(MIN(A29,175000)-145000)),0)),0)+IF(Inputs!B8="Additional / Investor",0.08*A29,0)),IF(Inputs!B7="Wales",(IF(Inputs!B8="Additional / Investor",(MIN(A29,180000)*0.05+MAX(0,MIN(A29,250000)-180000)*0.085+MAX(0,MIN(A29,400000)-250000)*0.1+MAX(0,MIN(A29,750000)-400000)*0.125+MAX(0,MIN(A29,1500000)-750000)*0.15+MAX(0,A29-1500000)*0.17),(MAX(0,MIN(A29,400000)-225000)*0.06+MAX(0,MIN(A29,750000)-400000)*0.075+MAX(0,MIN(A29,1500000)-750000)*0.1+MAX(0,A29-1500000)*0.12))),0)))))+(Inputs!B14+Inputs!B15+Inputs!B16+Inputs!B17)+(Summary!B14)+(Summary!B15)+(((((A29)*Inputs!B20)+(IF(Inputs!B24="Yes",(Summary!B14)*Inputs!B25,0))*Inputs!B26)*Inputs!B21*Inputs!B10/12)+((((A29)*Inputs!B20)+(IF(Inputs!B24="Yes",(Summary!B14)*Inputs!B25,0)))*Inputs!B22)+((((A29)*Inputs!B20)+(IF(Inputs!B24="Yes",(Summary!B14)*Inputs!B25,0)))*Inputs!B23))+(Summary!B17))) -> 68775 | C29: =IF(A29>$B$6,"","")
A30: =$B$5+(19)*$B$7 -> 195000 | B30: =IF(A30>$B$6,"",(Inputs!B6)-((A30)+(IF(Inputs!D13<>"",Inputs!D13,IF(Inputs!B7="England & N. Ireland",(IF(Inputs!B8="First-time buyer",(IF(A30<=500000,MAX(0,A30-300000)*0.05,(MAX(0,MIN(A30,250000)-125000)*0.02+MAX(0,MIN(A30,925000)-250000)*0.05+MAX(0,MIN(A30,1500000)-925000)*0.1+MAX(0,A30-1500000)*0.12))),(MAX(0,MIN(A30,250000)-125000)*0.02+MAX(0,MIN(A30,925000)-250000)*0.05+MAX(0,MIN(A30,1500000)-925000)*0.1+MAX(0,A30-1500000)*0.12)+IF(Inputs!B8="Additional / Investor",0.05*A30,0)+IF(Inputs!B9="Yes",0.02*A30,0))),IF(Inputs!B7="Scotland",((MAX(0,MIN(A30,250000)-145000)*0.02+MAX(0,MIN(A30,325000)-250000)*0.05+MAX(0,MIN(A30,750000)-325000)*0.1+MAX(0,A30-750000)*0.12)-IF(Inputs!B8="First-time buyer",(IF(A30>145000,MIN(600,0.02*(MIN(A30,175000)-145000)),0)),0)+IF(Inputs!B8="Additional / Investor",0.08*A30,0)),IF(Inputs!B7="Wales",(IF(Inputs!B8="Additional / Investor",(MIN(A30,180000)*0.05+MAX(0,MIN(A30,250000)-180000)*0.085+MAX(0,MIN(A30,400000)-250000)*0.1+MAX(0,MIN(A30,750000)-400000)*0.125+MAX(0,MIN(A30,1500000)-750000)*0.15+MAX(0,A30-1500000)*0.17),(MAX(0,MIN(A30,400000)-225000)*0.06+MAX(0,MIN(A30,750000)-400000)*0.075+MAX(0,MIN(A30,1500000)-750000)*0.1+MAX(0,A30-1500000)*0.12))),0)))))+(Inputs!B14+Inputs!B15+Inputs!B16+Inputs!B17)+(Summary!B14)+(Summary!B15)+(((((A30)*Inputs!B20)+(IF(Inputs!B24="Yes",(Summary!B14)*Inputs!B25,0))*Inputs!B26)*Inputs!B21*Inputs!B10/12)+((((A30)*Inputs!B20)+(IF(Inputs!B24="Yes",(Summary!B14)*Inputs!B25,0)))*Inputs!B22)+((((A30)*Inputs!B20)+(IF(Inputs!B24="Yes",(Summary!B14)*Inputs!B25,0)))*Inputs!B23))+(Summary!B17))) -> 63087.5 | C30: =IF(A30>$B$6,"","")
A31: =$B$5+(20)*$B$7 -> 200000 | B31: =IF(A31>$B$6,"",(Inputs!B6)-((A31)+(IF(Inputs!D13<>"",Inputs!D13,IF(Inputs!B7="England & N. Ireland",(IF(Inputs!B8="First-time buyer",(IF(A31<=500000,MAX(0,A31-300000)*0.05,(MAX(0,MIN(A31,250000)-125000)*0.02+MAX(0,MIN(A31,925000)-250000)*0.05+MAX(0,MIN(A31,1500000)-925000)*0.1+MAX(0,A31-1500000)*0.12))),(MAX(0,MIN(A31,250000)-125000)*0.02+MAX(0,MIN(A31,925000)-250000)*0.05+MAX(0,MIN(A31,1500000)-925000)*0.1+MAX(0,A31-1500000)*0.12)+IF(Inputs!B8="Additional / Investor",0.05*A31,0)+IF(Inputs!B9="Yes",0.02*A31,0))),IF(Inputs!B7="Scotland",((MAX(0,MIN(A31,250000)-145000)*0.02+MAX(0,MIN(A31,325000)-250000)*0.05+MAX(0,MIN(A31,750000)-325000)*0.1+MAX(0,A31-750000)*0.12)-IF(Inputs!B8="First-time buyer",(IF(A31>145000,MIN(600,0.02*(MIN(A31,175000)-145000)),0)),0)+IF(Inputs!B8="Additional / Investor",0.08*A31,0)),IF(Inputs!B7="Wales",(IF(Inputs!B8="Additional / Investor",(MIN(A31,180000)*0.05+MAX(0,MIN(A31,250000)-180000)*0.085+MAX(0,MIN(A31,400000)-250000)*0.1+MAX(0,MIN(A31,750000)-400000)*0.125+MAX(0,MIN(A31,1500000)-750000)*0.15+MAX(0,A31-1500000)*0.17),(MAX(0,MIN(A31,400000)-225000)*0.06+MAX(0,MIN(A31,750000)-400000)*0.075+MAX(0,MIN(A31,1500000)-750000)*0.1+MAX(0,A31-1500000)*0.12))),0)))))+(Inputs!B14+Inputs!B15+Inputs!B16+Inputs!B17)+(Summary!B14)+(Summary!B15)+(((((A31)*Inputs!B20)+(IF(Inputs!B24="Yes",(Summary!B14)*Inputs!B25,0))*Inputs!B26)*Inputs!B21*Inputs!B10/12)+((((A31)*Inputs!B20)+(IF(Inputs!B24="Yes",(Summary!B14)*Inputs!B25,0)))*Inputs!B22)+((((A31)*Inputs!B20)+(IF(Inputs!B24="Yes",(Summary!B14)*Inputs!B25,0)))*Inputs!B23))+(Summary!B17))) -> 57400 | C31: =IF(A31>$B$6,"","")
A32: =$B$5+(21)*$B$7 -> 205000 | B32: =IF(A32>$B$6,"",(Inputs!B6)-((A32)+(IF(Inputs!D13<>"",Inputs!D13,IF(Inputs!B7="England & N. Ireland",(IF(Inputs!B8="First-time buyer",(IF(A32<=500000,MAX(0,A32-300000)*0.05,(MAX(0,MIN(A32,250000)-125000)*0.02+MAX(0,MIN(A32,925000)-250000)*0.05+MAX(0,MIN(A32,1500000)-925000)*0.1+MAX(0,A32-1500000)*0.12))),(MAX(0,MIN(A32,250000)-125000)*0.02+MAX(0,MIN(A32,925000)-250000)*0.05+MAX(0,MIN(A32,1500000)-925000)*0.1+MAX(0,A32-1500000)*0.12)+IF(Inputs!B8="Additional / Investor",0.05*A32,0)+IF(Inputs!B9="Yes",0.02*A32,0))),IF(Inputs!B7="Scotland",((MAX(0,MIN(A32,250000)-145000)*0.02+MAX(0,MIN(A32,325000)-250000)*0.05+MAX(0,MIN(A32,750000)-325000)*0.1+MAX(0,A32-750000)*0.12)-IF(Inputs!B8="First-time buyer",(IF(A32>145000,MIN(600,0.02*(MIN(A32,175000)-145000)),0)),0)+IF(Inputs!B8="Additional / Investor",0.08*A32,0)),IF(Inputs!B7="Wales",(IF(Inputs!B8="Additional / Investor",(MIN(A32,180000)*0.05+MAX(0,MIN(A32,250000)-180000)*0.085+MAX(0,MIN(A32,400000)-250000)*0.1+MAX(0,MIN(A32,750000)-400000)*0.125+MAX(0,MIN(A32,1500000)-750000)*0.15+MAX(0,A32-1500000)*0.17),(MAX(0,MIN(A32,400000)-225000)*0.06+MAX(0,MIN(A32,750000)-400000)*0.075+MAX(0,MIN(A32,1500000)-750000)*0.1+MAX(0,A32-1500000)*0.12))),0)))))+(Inputs!B14+Inputs!B15+Inputs!B16+Inputs!B17)+(Summary!B14)+(Summary!B15)+(((((A32)*Inputs!B20)+(IF(Inputs!B24="Yes",(Summary!B14)*Inputs!B25,0))*Inputs!B26)*Inputs!B21*Inputs!B10/12)+((((A32)*Inputs!B20)+(IF(Inputs!B24="Yes",(Summary!B14)*Inputs!B25,0)))*Inputs!B22)+((((A32)*Inputs!B20)+(IF(Inputs!B24="Yes",(Summary!B14)*Inputs!B25,0)))*Inputs!B23))+(Summary!B17))) -> 51712.5 | C32: =IF(A32>$B$6,"","")
A33: =$B$5+(22)*$B$7 -> 210000 | B33: =IF(A33>$B$6,"",(Inputs!B6)-((A33)+(IF(Inputs!D13<>"",Inputs!D13,IF(Inputs!B7="England & N. Ireland",(IF(Inputs!B8="First-time buyer",(IF(A33<=500000,MAX(0,A33-300000)*0.05,(MAX(0,MIN(A33,250000)-125000)*0.02+MAX(0,MIN(A33,925000)-250000)*0.05+MAX(0,MIN(A33,1500000)-925000)*0.1+MAX(0,A33-1500000)*0.12))),(MAX(0,MIN(A33,250000)-125000)*0.02+MAX(0,MIN(A33,925000)-250000)*0.05+MAX(0,MIN(A33,1500000)-925000)*0.1+MAX(0,A33-1500000)*0.12)+IF(Inputs!B8="Additional / Investor",0.05*A33,0)+IF(Inputs!B9="Yes",0.02*A33,0))),IF(Inputs!B7="Scotland",((MAX(0,MIN(A33,250000)-145000)*0.02+MAX(0,MIN(A33,325000)-250000)*0.05+MAX(0,MIN(A33,750000)-325000)*0.1+MAX(0,A33-750000)*0.12)-IF(Inputs!B8="First-time buyer",(IF(A33>145000,MIN(600,0.02*(MIN(A33,175000)-145000)),0)),0)+IF(Inputs!B8="Additional / Investor",0.08*A33,0)),IF(Inputs!B7="Wales",(IF(Inputs!B8="Additional / Investor",(MIN(A33,180000)*0.05+MAX(0,MIN(A33,250000)-180000)*0.085+MAX(0,MIN(A33,400000)-250000)*0.1+MAX(0,MIN(A33,750000)-400000)*0.125+MAX(0,MIN(A33,1500000)-750000)*0.15+MAX(0,A33-1500000)*0.17),(MAX(0,MIN(A33,400000)-225000)*0.06+MAX(0,MIN(A33,750000)-400000)*0.075+MAX(0,MIN(A33,1500000)-750000)*0.1+MAX(0,A33-1500000)*0.12))),0)))))+(Inputs!B14+Inputs!B15+Inputs!B16+Inputs!B17)+(Summary!B14)+(Summary!B15)+(((((A33)*Inputs!B20)+(IF(Inputs!B24="Yes",(Summary!B14)*Inputs!B25,0))*Inputs!B26)*Inputs!B21*Inputs!B10/12)+((((A33)*Inputs!B20)+(IF(Inputs!B24="Yes",(Summary!B14)*Inputs!B25,0)))*Inputs!B22)+((((A33)*Inputs!B20)+(IF(Inputs!B24="Yes",(Summary!B14)*Inputs!B25,0)))*Inputs!B23))+(Summary!B17))) -> 46025 | C33: =IF(A33>$B$6,"","")
A34: =$B$5+(23)*$B$7 -> 215000 | B34: =IF(A34>$B$6,"",(Inputs!B6)-((A34)+(IF(Inputs!D13<>"",Inputs!D13,IF(Inputs!B7="England & N. Ireland",(IF(Inputs!B8="First-time buyer",(IF(A34<=500000,MAX(0,A34-300000)*0.05,(MAX(0,MIN(A34,250000)-125000)*0.02+MAX(0,MIN(A34,925000)-250000)*0.05+MAX(0,MIN(A34,1500000)-925000)*0.1+MAX(0,A34-1500000)*0.12))),(MAX(0,MIN(A34,250000)-125000)*0.02+MAX(0,MIN(A34,925000)-250000)*0.05+MAX(0,MIN(A34,1500000)-925000)*0.1+MAX(0,A34-1500000)*0.12)+IF(Inputs!B8="Additional / Investor",0.05*A34,0)+IF(Inputs!B9="Yes",0.02*A34,0))),IF(Inputs!B7="Scotland",((MAX(0,MIN(A34,250000)-145000)*0.02+MAX(0,MIN(A34,325000)-250000)*0.05+MAX(0,MIN(A34,750000)-325000)*0.1+MAX(0,A34-750000)*0.12)-IF(Inputs!B8="First-time buyer",(IF(A34>145000,MIN(600,0.02*(MIN(A34,175000)-145000)),0)),0)+IF(Inputs!B8="Additional / Investor",0.08*A34,0)),IF(Inputs!B7="Wales",(IF(Inputs!B8="Additional / Investor",(MIN(A34,180000)*0.05+MAX(0,MIN(A34,250000)-180000)*0.085+MAX(0,MIN(A34,400000)-250000)*0.1+MAX(0,MIN(A34,750000)-400000)*0.125+MAX(0,MIN(A34,1500000)-750000)*0.15+MAX(0,A34-1500000)*0.17),(MAX(0,MIN(A34,400000)-225000)*0.06+MAX(0,MIN(A34,750000)-400000)*0.075+MAX(0,MIN(A34,1500000)-750000)*0.1+MAX(0,A34-1500000)*0.12))),0)))))+(Inputs!B14+Inputs!B15+Inputs!B16+Inputs!B17)+(Summary!B14)+(Summary!B15)+(((((A34)*Inputs!B20)+(IF(Inputs!B24="Yes",(Summary!B14)*Inputs!B25,0))*Inputs!B26)*Inputs!B21*Inputs!B10/12)+((((A34)*Inputs!B20)+(IF(Inputs!B24="Yes",(Summary!B14)*Inputs!B25,0)))*Inputs!B22)+((((A34)*Inputs!B20)+(IF(Inputs!B24="Yes",(Summary!B14)*Inputs!B25,0)))*Inputs!B23))+(Summary!B17))) -> 40337.5 | C34: =IF(A34>$B$6,"","")
A35: =$B$5+(24)*$B$7 -> 220000 | B35: =IF(A35>$B$6,"",(Inputs!B6)-((A35)+(IF(Inputs!D13<>"",Inputs!D13,IF(Inputs!B7="England & N. Ireland",(IF(Inputs!B8="First-time buyer",(IF(A35<=500000,MAX(0,A35-300000)*0.05,(MAX(0,MIN(A35,250000)-125000)*0.02+MAX(0,MIN(A35,925000)-250000)*0.05+MAX(0,MIN(A35,1500000)-925000)*0.1+MAX(0,A35-1500000)*0.12))),(MAX(0,MIN(A35,250000)-125000)*0.02+MAX(0,MIN(A35,925000)-250000)*0.05+MAX(0,MIN(A35,1500000)-925000)*0.1+MAX(0,A35-1500000)*0.12)+IF(Inputs!B8="Additional / Investor",0.05*A35,0)+IF(Inputs!B9="Yes",0.02*A35,0))),IF(Inputs!B7="Scotland",((MAX(0,MIN(A35,250000)-145000)*0.02+MAX(0,MIN(A35,325000)-250000)*0.05+MAX(0,MIN(A35,750000)-325000)*0.1+MAX(0,A35-750000)*0.12)-IF(Inputs!B8="First-time buyer",(IF(A35>145000,MIN(600,0.02*(MIN(A35,175000)-145000)),0)),0)+IF(Inputs!B8="Additional / Investor",0.08*A35,0)),IF(Inputs!B7="Wales",(IF(Inputs!B8="Additional / Investor",(MIN(A35,180000)*0.05+MAX(0,MIN(A35,250000)-180000)*0.085+MAX(0,MIN(A35,400000)-250000)*0.1+MAX(0,MIN(A35,750000)-400000)*0.125+MAX(0,MIN(A35,1500000)-750000)*0.15+MAX(0,A35-1500000)*0.17),(MAX(0,MIN(A35,400000)-225000)*0.06+MAX(0,MIN(A35,750000)-400000)*0.075+MAX(0,MIN(A35,1500000)-750000)*0.1+MAX(0,A35-1500000)*0.12))),0)))))+(Inputs!B14+Inputs!B15+Inputs!B16+Inputs!B17)+(Summary!B14)+(Summary!B15)+(((((A35)*Inputs!B20)+(IF(Inputs!B24="Yes",(Summary!B14)*Inputs!B25,0))*Inputs!B26)*Inputs!B21*Inputs!B10/12)+((((A35)*Inputs!B20)+(IF(Inputs!B24="Yes",(Summary!B14)*Inputs!B25,0)))*Inputs!B22)+((((A35)*Inputs!B20)+(IF(Inputs!B24="Yes",(Summary!B14)*Inputs!B25,0)))*Inputs!B23))+(Summary!B17))) -> 34650 | C35: =IF(A35>$B$6,"","")
A36: =$B$5+(25)*$B$7 -> 225000 | B36: =IF(A36>$B$6,"",(Inputs!B6)-((A36)+(IF(Inputs!D13<>"",Inputs!D13,IF(Inputs!B7="England & N. Ireland",(IF(Inputs!B8="First-time buyer",(IF(A36<=500000,MAX(0,A36-300000)*0.05,(MAX(0,MIN(A36,250000)-125000)*0.02+MAX(0,MIN(A36,925000)-250000)*0.05+MAX(0,MIN(A36,1500000)-925000)*0.1+MAX(0,A36-1500000)*0.12))),(MAX(0,MIN(A36,250000)-125000)*0.02+MAX(0,MIN(A36,925000)-250000)*0.05+MAX(0,MIN(A36,1500000)-925000)*0.1+MAX(0,A36-1500000)*0.12)+IF(Inputs!B8="Additional / Investor",0.05*A36,0)+IF(Inputs!B9="Yes",0.02*A36,0))),IF(Inputs!B7="Scotland",((MAX(0,MIN(A36,250000)-145000)*0.02+MAX(0,MIN(A36,325000)-250000)*0.05+MAX(0,MIN(A36,750000)-325000)*0.1+MAX(0,A36-750000)*0.12)-IF(Inputs!B8="First-time buyer",(IF(A36>145000,MIN(600,0.02*(MIN(A36,175000)-145000)),0)),0)+IF(Inputs!B8="Additional / Investor",0.08*A36,0)),IF(Inputs!B7="Wales",(IF(Inputs!B8="Additional / Investor",(MIN(A36,180000)*0.05+MAX(0,MIN(A36,250000)-180000)*0.085+MAX(0,MIN(A36,400000)-250000)*0.1+MAX(0,MIN(A36,750000)-400000)*0.125+MAX(0,MIN(A36,1500000)-750000)*0.15+MAX(0,A36-1500000)*0.17),(MAX(0,MIN(A36,400000)-225000)*0.06+MAX(0,MIN(A36,750000)-400000)*0.075+MAX(0,MIN(A36,1500000)-750000)*0.1+MAX(0,A36-1500000)*0.12))),0)))))+(Inputs!B14+Inputs!B15+Inputs!B16+Inputs!B17)+(Summary!B14)+(Summary!B15)+(((((A36)*Inputs!B20)+(IF(Inputs!B24="Yes",(Summary!B14)*Inputs!B25,0))*Inputs!B26)*Inputs!B21*Inputs!B10/12)+((((A36)*Inputs!B20)+(IF(Inputs!B24="Yes",(Summary!B14)*Inputs!B25,0)))*Inputs!B22)+((((A36)*Inputs!B20)+(IF(Inputs!B24="Yes",(Summary!B14)*Inputs!B25,0)))*Inputs!B23))+(Summary!B17))) -> 28962.5 | C36: =IF(A36>$B$6,"","")
A37: =$B$5+(26)*$B$7 -> 230000 | B37: =IF(A37>$B$6,"",(Inputs!B6)-((A37)+(IF(Inputs!D13<>"",Inputs!D13,IF(Inputs!B7="England & N. Ireland",(IF(Inputs!B8="First-time buyer",(IF(A37<=500000,MAX(0,A37-300000)*0.05,(MAX(0,MIN(A37,250000)-125000)*0.02+MAX(0,MIN(A37,925000)-250000)*0.05+MAX(0,MIN(A37,1500000)-925000)*0.1+MAX(0,A37-1500000)*0.12))),(MAX(0,MIN(A37,250000)-125000)*0.02+MAX(0,MIN(A37,925000)-250000)*0.05+MAX(0,MIN(A37,1500000)-925000)*0.1+MAX(0,A37-1500000)*0.12)+IF(Inputs!B8="Additional / Investor",0.05*A37,0)+IF(Inputs!B9="Yes",0.02*A37,0))),IF(Inputs!B7="Scotland",((MAX(0,MIN(A37,250000)-145000)*0.02+MAX(0,MIN(A37,325000)-250000)*0.05+MAX(0,MIN(A37,750000)-325000)*0.1+MAX(0,A37-750000)*0.12)-IF(Inputs!B8="First-time buyer",(IF(A37>145000,MIN(600,0.02*(MIN(A37,175000)-145000)),0)),0)+IF(Inputs!B8="Additional / Investor",0.08*A37,0)),IF(Inputs!B7="Wales",(IF(Inputs!B8="Additional / Investor",(MIN(A37,180000)*0.05+MAX(0,MIN(A37,250000)-180000)*0.085+MAX(0,MIN(A37,400000)-250000)*0.1+MAX(0,MIN(A37,750000)-400000)*0.125+MAX(0,MIN(A37,1500000)-750000)*0.15+MAX(0,A37-1500000)*0.17),(MAX(0,MIN(A37,400000)-225000)*0.06+MAX(0,MIN(A37,750000)-400000)*0.075+MAX(0,MIN(A37,1500000)-750000)*0.1+MAX(0,A37-1500000)*0.12))),0)))))+(Inputs!B14+Inputs!B15+Inputs!B16+Inputs!B17)+(Summary!B14)+(Summary!B15)+(((((A37)*Inputs!B20)+(IF(Inputs!B24="Yes",(Summary!B14)*Inputs!B25,0))*Inputs!B26)*Inputs!B21*Inputs!B10/12)+((((A37)*Inputs!B20)+(IF(Inputs!B24="Yes",(Summary!B14)*Inputs!B25,0)))*Inputs!B22)+((((A37)*Inputs!B20)+(IF(Inputs!B24="Yes",(Summary!B14)*Inputs!B25,0)))*Inputs!B23))+(Summary!B17))) -> 23275 | C37: =IF(A37>$B$6,"","")
A38: =$B$5+(27)*$B$7 -> 235000 | B38: =IF(A38>$B$6,"",(Inputs!B6)-((A38)+(IF(Inputs!D13<>"",Inputs!D13,IF(Inputs!B7="England & N. Ireland",(IF(Inputs!B8="First-time buyer",(IF(A38<=500000,MAX(0,A38-300000)*0.05,(MAX(0,MIN(A38,250000)-125000)*0.02+MAX(0,MIN(A38,925000)-250000)*0.05+MAX(0,MIN(A38,1500000)-925000)*0.1+MAX(0,A38-1500000)*0.12))),(MAX(0,MIN(A38,250000)-125000)*0.02+MAX(0,MIN(A38,925000)-250000)*0.05+MAX(0,MIN(A38,1500000)-925000)*0.1+MAX(0,A38-1500000)*0.12)+IF(Inputs!B8="Additional / Investor",0.05*A38,0)+IF(Inputs!B9="Yes",0.02*A38,0))),IF(Inputs!B7="Scotland",((MAX(0,MIN(A38,250000)-145000)*0.02+MAX(0,MIN(A38,325000)-250000)*0.05+MAX(0,MIN(A38,750000)-325000)*0.1+MAX(0,A38-750000)*0.12)-IF(Inputs!B8="First-time buyer",(IF(A38>145000,MIN(600,0.02*(MIN(A38,175000)-145000)),0)),0)+IF(Inputs!B8="Additional / Investor",0.08*A38,0)),IF(Inputs!B7="Wales",(IF(Inputs!B8="Additional / Investor",(MIN(A38,180000)*0.05+MAX(0,MIN(A38,250000)-180000)*0.085+MAX(0,MIN(A38,400000)-250000)*0.1+MAX(0,MIN(A38,750000)-400000)*0.125+MAX(0,MIN(A38,1500000)-750000)*0.15+MAX(0,A38-1500000)*0.17),(MAX(0,MIN(A38,400000)-225000)*0.06+MAX(0,MIN(A38,750000)-400000)*0.075+MAX(0,MIN(A38,1500000)-750000)*0.1+MAX(0,A38-1500000)*0.12))),0)))))+(Inputs!B14+Inputs!B15+Inputs!B16+Inputs!B17)+(Summary!B14)+(Summary!B15)+(((((A38)*Inputs!B20)+(IF(Inputs!B24="Yes",(Summary!B14)*Inputs!B25,0))*Inputs!B26)*Inputs!B21*Inputs!B10/12)+((((A38)*Inputs!B20)+(IF(Inputs!B24="Yes",(Summary!B14)*Inputs!B25,0)))*Inputs!B22)+((((A38)*Inputs!B20)+(IF(Inputs!B24="Yes",(Summary!B14)*Inputs!B25,0)))*Inputs!B23))+(Summary!B17))) -> 17587.5 | C38: =IF(A38>$B$6,"","")
A39: =$B$5+(28)*$B$7 -> 240000 | B39: =IF(A39>$B$6,"",(Inputs!B6)-((A39)+(IF(Inputs!D13<>"",Inputs!D13,IF(Inputs!B7="England & N. Ireland",(IF(Inputs!B8="First-time buyer",(IF(A39<=500000,MAX(0,A39-300000)*0.05,(MAX(0,MIN(A39,250000)-125000)*0.02+MAX(0,MIN(A39,925000)-250000)*0.05+MAX(0,MIN(A39,1500000)-925000)*0.1+MAX(0,A39-1500000)*0.12))),(MAX(0,MIN(A39,250000)-125000)*0.02+MAX(0,MIN(A39,925000)-250000)*0.05+MAX(0,MIN(A39,1500000)-925000)*0.1+MAX(0,A39-1500000)*0.12)+IF(Inputs!B8="Additional / Investor",0.05*A39,0)+IF(Inputs!B9="Yes",0.02*A39,0))),IF(Inputs!B7="Scotland",((MAX(0,MIN(A39,250000)-145000)*0.02+MAX(0,MIN(A39,325000)-250000)*0.05+MAX(0,MIN(A39,750000)-325000)*0.1+MAX(0,A39-750000)*0.12)-IF(Inputs!B8="First-time buyer",(IF(A39>145000,MIN(600,0.02*(MIN(A39,175000)-145000)),0)),0)+IF(Inputs!B8="Additional / Investor",0.08*A39,0)),IF(Inputs!B7="Wales",(IF(Inputs!B8="Additional / Investor",(MIN(A39,180000)*0.05+MAX(0,MIN(A39,250000)-180000)*0.085+MAX(0,MIN(A39,400000)-250000)*0.1+MAX(0,MIN(A39,750000)-400000)*0.125+MAX(0,MIN(A39,1500000)-750000)*0.15+MAX(0,A39-1500000)*0.17),(MAX(0,MIN(A39,400000)-225000)*0.06+MAX(0,MIN(A39,750000)-400000)*0.075+MAX(0,MIN(A39,1500000)-750000)*0.1+MAX(0,A39-1500000)*0.12))),0)))))+(Inputs!B14+Inputs!B15+Inputs!B16+Inputs!B17)+(Summary!B14)+(Summary!B15)+(((((A39)*Inputs!B20)+(IF(Inputs!B24="Yes",(Summary!B14)*Inputs!B25,0))*Inputs!B26)*Inputs!B21*Inputs!B10/12)+((((A39)*Inputs!B20)+(IF(Inputs!B24="Yes",(Summary!B14)*Inputs!B25,0)))*Inputs!B22)+((((A39)*Inputs!B20)+(IF(Inputs!B24="Yes",(Summary!B14)*Inputs!B25,0)))*Inputs!B23))+(Summary!B17))) -> 11900 | C39: =IF(A39>$B$6,"","")
A40: =$B$5+(29)*$B$7 -> 245000 | B40: =IF(A40>$B$6,"",(Inputs!B6)-((A40)+(IF(Inputs!D13<>"",Inputs!D13,IF(Inputs!B7="England & N. Ireland",(IF(Inputs!B8="First-time buyer",(IF(A40<=500000,MAX(0,A40-300000)*0.05,(MAX(0,MIN(A40,250000)-125000)*0.02+MAX(0,MIN(A40,925000)-250000)*0.05+MAX(0,MIN(A40,1500000)-925000)*0.1+MAX(0,A40-1500000)*0.12))),(MAX(0,MIN(A40,250000)-125000)*0.02+MAX(0,MIN(A40,925000)-250000)*0.05+MAX(0,MIN(A40,1500000)-925000)*0.1+MAX(0,A40-1500000)*0.12)+IF(Inputs!B8="Additional / Investor",0.05*A40,0)+IF(Inputs!B9="Yes",0.02*A40,0))),IF(Inputs!B7="Scotland",((MAX(0,MIN(A40,250000)-145000)*0.02+MAX(0,MIN(A40,325000)-250000)*0.05+MAX(0,MIN(A40,750000)-325000)*0.1+MAX(0,A40-750000)*0.12)-IF(Inputs!B8="First-time buyer",(IF(A40>145000,MIN(600,0.02*(MIN(A40,175000)-145000)),0)),0)+IF(Inputs!B8="Additional / Investor",0.08*A40,0)),IF(Inputs!B7="Wales",(IF(Inputs!B8="Additional / Investor",(MIN(A40,180000)*0.05+MAX(0,MIN(A40,250000)-180000)*0.085+MAX(0,MIN(A40,400000)-250000)*0.1+MAX(0,MIN(A40,750000)-400000)*0.125+MAX(0,MIN(A40,1500000)-750000)*0.15+MAX(0,A40-1500000)*0.17),(MAX(0,MIN(A40,400000)-225000)*0.06+MAX(0,MIN(A40,750000)-400000)*0.075+MAX(0,MIN(A40,1500000)-750000)*0.1+MAX(0,A40-1500000)*0.12))),0)))))+(Inputs!B14+Inputs!B15+Inputs!B16+Inputs!B17)+(Summary!B14)+(Summary!B15)+(((((A40)*Inputs!B20)+(IF(Inputs!B24="Yes",(Summary!B14)*Inputs!B25,0))*Inputs!B26)*Inputs!B21*Inputs!B10/12)+((((A40)*Inputs!B20)+(IF(Inputs!B24="Yes",(Summary!B14)*Inputs!B25,0)))*Inputs!B22)+((((A40)*Inputs!B20)+(IF(Inputs!B24="Yes",(Summary!B14)*Inputs!B25,0)))*Inputs!B23))+(Summary!B17))) -> 6212.5 | C40: =IF(A40>$B$6,"","")
A41: =$B$5+(30)*$B$7 -> 250000 | B41: =IF(A41>$B$6,"",(Inputs!B6)-((A41)+(IF(Inputs!D13<>"",Inputs!D13,IF(Inputs!B7="England & N. Ireland",(IF(Inputs!B8="First-time buyer",(IF(A41<=500000,MAX(0,A41-300000)*0.05,(MAX(0,MIN(A41,250000)-125000)*0.02+MAX(0,MIN(A41,925000)-250000)*0.05+MAX(0,MIN(A41,1500000)-925000)*0.1+MAX(0,A41-1500000)*0.12))),(MAX(0,MIN(A41,250000)-125000)*0.02+MAX(0,MIN(A41,925000)-250000)*0.05+MAX(0,MIN(A41,1500000)-925000)*0.1+MAX(0,A41-1500000)*0.12)+IF(Inputs!B8="Additional / Investor",0.05*A41,0)+IF(Inputs!B9="Yes",0.02*A41,0))),IF(Inputs!B7="Scotland",((MAX(0,MIN(A41,250000)-145000)*0.02+MAX(0,MIN(A41,325000)-250000)*0.05+MAX(0,MIN(A41,750000)-325000)*0.1+MAX(0,A41-750000)*0.12)-IF(Inputs!B8="First-time buyer",(IF(A41>145000,MIN(600,0.02*(MIN(A41,175000)-145000)),0)),0)+IF(Inputs!B8="Additional / Investor",0.08*A41,0)),IF(Inputs!B7="Wales",(IF(Inputs!B8="Additional / Investor",(MIN(A41,180000)*0.05+MAX(0,MIN(A41,250000)-180000)*0.085+MAX(0,MIN(A41,400000)-250000)*0.1+MAX(0,MIN(A41,750000)-400000)*0.125+MAX(0,MIN(A41,1500000)-750000)*0.15+MAX(0,A41-1500000)*0.17),(MAX(0,MIN(A41,400000)-225000)*0.06+MAX(0,MIN(A41,750000)-400000)*0.075+MAX(0,MIN(A41,1500000)-750000)*0.1+MAX(0,A41-1500000)*0.12))),0)))))+(Inputs!B14+Inputs!B15+Inputs!B16+Inputs!B17)+(Summary!B14)+(Summary!B15)+(((((A41)*Inputs!B20)+(IF(Inputs!B24="Yes",(Summary!B14)*Inputs!B25,0))*Inputs!B26)*Inputs!B21*Inputs!B10/12)+((((A41)*Inputs!B20)+(IF(Inputs!B24="Yes",(Summary!B14)*Inputs!B25,0)))*Inputs!B22)+((((A41)*Inputs!B20)+(IF(Inputs!B24="Yes",(Summary!B14)*Inputs!B25,0)))*Inputs!B23))+(Summary!B17))) -> 525 | C41: =IF(A41>$B$6,"","")
A42: =$B$5+(31)*$B$7 -> 255000 | B42: =IF(A42>$B$6,"",(Inputs!B6)-((A42)+(IF(Inputs!D13<>"",Inputs!D13,IF(Inputs!B7="England & N. Ireland",(IF(Inputs!B8="First-time buyer",(IF(A42<=500000,MAX(0,A42-300000)*0.05,(MAX(0,MIN(A42,250000)-125000)*0.02+MAX(0,MIN(A42,925000)-250000)*0.05+MAX(0,MIN(A42,1500000)-925000)*0.1+MAX(0,A42-1500000)*0.12))),(MAX(0,MIN(A42,250000)-125000)*0.02+MAX(0,MIN(A42,925000)-250000)*0.05+MAX(0,MIN(A42,1500000)-925000)*0.1+MAX(0,A42-1500000)*0.12)+IF(Inputs!B8="Additional / Investor",0.05*A42,0)+IF(Inputs!B9="Yes",0.02*A42,0))),IF(Inputs!B7="Scotland",((MAX(0,MIN(A42,250000)-145000)*0.02+MAX(0,MIN(A42,325000)-250000)*0.05+MAX(0,MIN(A42,750000)-325000)*0.1+MAX(0,A42-750000)*0.12)-IF(Inputs!B8="First-time buyer",(IF(A42>145000,MIN(600,0.02*(MIN(A42,175000)-145000)),0)),0)+IF(Inputs!B8="Additional / Investor",0.08*A42,0)),IF(Inputs!B7="Wales",(IF(Inputs!B8="Additional / Investor",(MIN(A42,180000)*0.05+MAX(0,MIN(A42,250000)-180000)*0.085+MAX(0,MIN(A42,400000)-250000)*0.1+MAX(0,MIN(A42,750000)-400000)*0.125+MAX(0,MIN(A42,1500000)-750000)*0.15+MAX(0,A42-1500000)*0.17),(MAX(0,MIN(A42,400000)-225000)*0.06+MAX(0,MIN(A42,750000)-400000)*0.075+MAX(0,MIN(A42,1500000)-750000)*0.1+MAX(0,A42-1500000)*0.12))),0)))))+(Inputs!B14+Inputs!B15+Inputs!B16+Inputs!B17)+(Summary!B14)+(Summary!B15)+(((((A42)*Inputs!B20)+(IF(Inputs!B24="Yes",(Summary!B14)*Inputs!B25,0))*Inputs!B26)*Inputs!B21*Inputs!B10/12)+((((A42)*Inputs!B20)+(IF(Inputs!B24="Yes",(Summary!B14)*Inputs!B25,0)))*Inputs!B22)+((((A42)*Inputs!B20)+(IF(Inputs!B24="Yes",(Summary!B14)*Inputs!B25,0)))*Inputs!B23))+(Summary!B17))) -> -5312.5 | C42: =IF(A42>$B$6,"","")
A43: =$B$5+(32)*$B$7 -> 260000 | B43: =IF(A43>$B$6,"",(Inputs!B6)-((A43)+(IF(Inputs!D13<>"",Inputs!D13,IF(Inputs!B7="England & N. Ireland",(IF(Inputs!B8="First-time buyer",(IF(A43<=500000,MAX(0,A43-300000)*0.05,(MAX(0,MIN(A43,250000)-125000)*0.02+MAX(0,MIN(A43,925000)-250000)*0.05+MAX(0,MIN(A43,1500000)-925000)*0.1+MAX(0,A43-1500000)*0.12))),(MAX(0,MIN(A43,250000)-125000)*0.02+MAX(0,MIN(A43,925000)-250000)*0.05+MAX(0,MIN(A43,1500000)-925000)*0.1+MAX(0,A43-1500000)*0.12)+IF(Inputs!B8="Additional / Investor",0.05*A43,0)+IF(Inputs!B9="Yes",0.02*A43,0))),IF(Inputs!B7="Scotland",((MAX(0,MIN(A43,250000)-145000)*0.02+MAX(0,MIN(A43,325000)-250000)*0.05+MAX(0,MIN(A43,750000)-325000)*0.1+MAX(0,A43-750000)*0.12)-IF(Inputs!B8="First-time buyer",(IF(A43>145000,MIN(600,0.02*(MIN(A43,175000)-145000)),0)),0)+IF(Inputs!B8="Additional / Investor",0.08*A43,0)),IF(Inputs!B7="Wales",(IF(Inputs!B8="Additional / Investor",(MIN(A43,180000)*0.05+MAX(0,MIN(A43,250000)-180000)*0.085+MAX(0,MIN(A43,400000)-250000)*0.1+MAX(0,MIN(A43,750000)-400000)*0.125+MAX(0,MIN(A43,1500000)-750000)*0.15+MAX(0,A43-1500000)*0.17),(MAX(0,MIN(A43,400000)-225000)*0.06+MAX(0,MIN(A43,750000)-400000)*0.075+MAX(0,MIN(A43,1500000)-750000)*0.1+MAX(0,A43-1500000)*0.12))),0)))))+(Inputs!B14+Inputs!B15+Inputs!B16+Inputs!B17)+(Summary!B14)+(Summary!B15)+(((((A43)*Inputs!B20)+(IF(Inputs!B24="Yes",(Summary!B14)*Inputs!B25,0))*Inputs!B26)*Inputs!B21*Inputs!B10/12)+((((A43)*Inputs!B20)+(IF(Inputs!B24="Yes",(Summary!B14)*Inputs!B25,0)))*Inputs!B22)+((((A43)*Inputs!B20)+(IF(Inputs!B24="Yes",(Summary!B14)*Inputs!B25,0)))*Inputs!B23))+(Summary!B17))) -> -11150 | C43: =IF(A43>$B$6,"","")
...

Sheet Sensitivity
A1: Sensitivity (Profit) — Sale Price vs Refurb Cost
A2: Shows how profit changes if sale price or refurb costs move. (All other inputs held constant.)
